Workbook
Name SegmentaciónDeDatos_Proveedor: #N/A
Name SegmentaciónDeDatos_RUBRO: #N/A
Name SegmentaciónDeDatos_SUBRUBRO: #N/A
Name SegmentaciónDeDatos_Tipo_de_insumo: #N/A

Sheet Insumos y gastos
C4: Tabla de insumos | J4: Tabla de costo de tintas
C5: Organiza los costos de tus insumos, nombres de proveedores y cantidades ❤ | J5: Por modelo de impresora ❤
J6: Nombre impresora | L6: Nombre impresora | N6: Nombre impresora | P6: Nombre Impresora | R6: Nombre Impresora | T6: Nombre impresora
J7: Color | K7: Precio | L7: Color | M7: Precio | N7: Color | O7: Precio | P7: Color | Q7: Precio | R7: Color | S7: Precio | T7: Color | U7: Precio
J8: Magenta | L8: Magenta | N8: Magenta | P8: Magenta | R8: Magenta | T8: Magenta
J9: Cyan | L9: Cyan | N9: Cyan | P9: Cyan | R9: Cyan | T9: Cyan
J10: Amarillo | L10: Amarillo | N10: Amarillo | P10: Amarillo | R10: Amarillo | T10: Amarillo
J11: Negro | L11: Negro | N11: Negro | P11: Negro | R11: Negro | T11: Negro
J12: Total | K12: =SUM(K8:K11) -> 0 | L12: Total | M12: =SUM(M8:M11) -> 0 | N12: Total | O12: =SUM(O8:O11) -> 0 | P12: Total | Q12: =SUM(Q8:Q11) -> 0 | R12: Total | S12: =SUM(S8:S11) -> 0 | T12: Total | U12: =SUM(U8:U11) -> 0
C13: Tipo de insumo | D13: Proveedor | E13: Nombre insumo | F13: Cant. Bulto | G13: Pr. costo bulto | H13: Pr. Unidad | J13: Cantidad impresa | L13: Cantidad impresa | N13: Cantidad impresa | P13: Cantidad impresa | R13: Cantidad impresa | T13: Cantidad impresa
B14: =Tabla1[[#This Row],[Nombre insumo]] -> Boreal Obra 80gr | C14: PAPEL | D14: EYPAPEL! | E14: Boreal Obra 80gr | F14: 500 | G14: 6683 | H14: =Tabla1[[#This Row],[Pr. costo bulto]]/Tabla1[[#This Row],[Cant. Bulto]] -> 13.366 | J14: Valor por hoja | K14: =K12/K13 -> #DIV/0! | L14: Valor por hoja | M14: =M12/M13 -> #DIV/0! | N14: Valor por hoja | O14: =O12/O13 -> #DIV/0! | P14: Valor por hoja | Q14: =Q12/Q13 -> #DIV/0! | R14: Valor por hoja | S14: =S12/S13 -> #DIV/0! | T14: Valor por hoja | U14: =U12/U13 -> #DIV/0!
B15: =Tabla1[[#This Row],[Nombre insumo]] -> 0 | H15: =Tabla1[[#This Row],[Pr. costo bulto]]/Tabla1[[#This Row],[Cant. Bulto]] -> #DIV/0! | J15: Valor con desgaste | L15: Valor con desgaste | N15: Valor con desgaste | P15: Valor con desgaste | R15: Valor con desgaste | T15: Valor con desgaste
B16: =Tabla1[[#This Row],[Nombre insumo]] -> 0 | H16: =Tabla1[[#This Row],[Pr. costo bulto]]/Tabla1[[#This Row],[Cant. Bulto]] -> #DIV/0!
B17: =Tabla1[[#This Row],[Nombre insumo]] -> 0 | H17: =Tabla1[[#This Row],[Pr. costo bulto]]/Tabla1[[#This Row],[Cant. Bulto]] -> #DIV/0!
B18: =Tabla1[[#This Row],[Nombre insumo]] -> 0 | H18: =Tabla1[[#This Row],[Pr. costo bulto]]/Tabla1[[#This Row],[Cant. Bulto]] -> #DIV/0!
B19: =Tabla1[[#This Row],[Nombre insumo]] -> 0 | H19: =Tabla1[[#This Row],[Pr. costo bulto]]/Tabla1[[#This Row],[Cant. Bulto]] -> #DIV/0!
B20: =Tabla1[[#This Row],[Nombre insumo]] -> 0 | H20: =Tabla1[[#This Row],[Pr. costo bulto]]/Tabla1[[#This Row],[Cant. Bulto]] -> #DIV/0! | J20: Tabla de costos | P20: Mano de obra
B21: =Tabla1[[#This Row],[Nombre insumo]] -> 0 | H21: =Tabla1[[#This Row],[Pr. costo bulto]]/Tabla1[[#This Row],[Cant. Bulto]] -> #DIV/0!
B22: =Tabla1[[#This Row],[Nombre insumo]] -> 0 | H22: =Tabla1[[#This Row],[Pr. costo bulto]]/Tabla1[[#This Row],[Cant. Bulto]] -> #DIV/0! | J22: Los costos fijos mensuales organizados ❤ | P22: Valorá tu tiempo y tu trabajo ❤
B23: =Tabla1[[#This Row],[Nombre insumo]] -> 0 | H23: =Tabla1[[#This Row],[Pr. costo bulto]]/Tabla1[[#This Row],[Cant. Bulto]] -> #DIV/0!
B24: =Tabla1[[#This Row],[Nombre insumo]] -> 0 | H24: =Tabla1[[#This Row],[Pr. costo bulto]]/Tabla1[[#This Row],[Cant. Bulto]] -> #DIV/0! | J24: Tipo de costo | K24: Valor mensual | L24: Por día | M24: Por hora (*) | P24: Valor por hora
B25: =Tabla1[[#This Row],[Nombre insumo]] -> 0 | H25: =Tabla1[[#This Row],[Pr. costo bulto]]/Tabla1[[#This Row],[Cant. Bulto]] -> #DIV/0! | J25: - | L25: =K25/30 -> 0 | M25: =L25/10 -> 0 | P25: Valor por dia | Q25: =Q24*10 -> 0
B26: =Tabla1[[#This Row],[Nombre insumo]] -> 0 | H26: =Tabla1[[#This Row],[Pr. costo bulto]]/Tabla1[[#This Row],[Cant. Bulto]] -> #DIV/0! | J26: - | L26: =K26/30 -> 0 | M26: =L26/10 -> 0 | P26: Valor por semana | Q26: =Q25*5 -> 0
B27: =Tabla1[[#This Row],[Nombre insumo]] -> 0 | H27: =Tabla1[[#This Row],[Pr. costo bulto]]/Tabla1[[#This Row],[Cant. Bulto]] -> #DIV/0! | J27: - | L27: =K27/30 -> 0 | M27: =L27/10 -> 0 | P27: Valor por mes | Q27: =Q25*20 -> 0
B28: =Tabla1[[#This Row],[Nombre insumo]] -> 0 | H28: =Tabla1[[#This Row],[Pr. costo bulto]]/Tabla1[[#This Row],[Cant. Bulto]] -> #DIV/0! | J28: - | L28: =K28/30 -> 0 | M28: =L28/10 -> 0 | P28: (*) Calculado en base a 10 horas de trabajo 5 dias a la semana
B29: =Tabla1[[#This Row],[Nombre insumo]] -> 0 | H29: =Tabla1[[#This Row],[Pr. costo bulto]]/Tabla1[[#This Row],[Cant. Bulto]] -> #DIV/0! | J29: - | L29: =K29/30 -> 0 | M29: =L29/10 -> 0
B30: =Tabla1[[#This Row],[Nombre insumo]] -> 0 | H30: =Tabla1[[#This Row],[Pr. costo bulto]]/Tabla1[[#This Row],[Cant. Bulto]] -> #DIV/0! | J30: - | L30: =K30/30 -> 0 | M30: =L30/10 -> 0
B31: =Tabla1[[#This Row],[Nombre insumo]] -> 0 | H31: =Tabla1[[#This Row],[Pr. costo bulto]]/Tabla1[[#This Row],[Cant. Bulto]] -> #DIV/0! | J31: - | L31: =K31/30 -> 0 | M31: =L31/10 -> 0
B32: =Tabla1[[#This Row],[Nombre insumo]] -> 0 | H32: =Tabla1[[#This Row],[Pr. costo bulto]]/Tabla1[[#This Row],[Cant. Bulto]] -> #DIV/0! | J32: - | L32: =K32/30 -> 0 | M32: =L32/10 -> 0
B33: =Tabla1[[#This Row],[Nombre insumo]] -> 0 | H33: =Tabla1[[#This Row],[Pr. costo bulto]]/Tabla1[[#This Row],[Cant. Bulto]] -> #DIV/0! | J33: - | L33: =K33/30 -> 0 | M33: =L33/10 -> 0
B34: =Tabla1[[#This Row],[Nombre insumo]] -> 0 | H34: =Tabla1[[#This Row],[Pr. costo bulto]]/Tabla1[[#This Row],[Cant. Bulto]] -> #DIV/0! | J34: - | L34: =K34/30 -> 0 | M34: =L34/10 -> 0
B35: =Tabla1[[#This Row],[Nombre insumo]] -> 0 | H35: =Tabla1[[#This Row],[Pr. costo bulto]]/Tabla1[[#This Row],[Cant. Bulto]] -> #DIV/0! | J35: - | L35: =K35/30 -> 0 | M35: =L35/10 -> 0
B36: =Tabla1[[#This Row],[Nombre insumo]] -> 0 | H36: =Tabla1[[#This Row],[Pr. costo bulto]]/Tabla1[[#This Row],[Cant. Bulto]] -> #DIV/0! | J36: - | L36: =K36/30 -> 0 | M36: =L36/10 -> 0
B37: =Tabla1[[#This Row],[Nombre insumo]] -> 0 | H37: =Tabla1[[#This Row],[Pr. costo bulto]]/Tabla1[[#This Row],[Cant. Bulto]] -> #DIV/0! | J37: - | L37: =K37/30 -> 0 | M37: =L37/10 -> 0
B38: =Tabla1[[#This Row],[Nombre insumo]] -> 0 | H38: =Tabla1[[#This Row],[Pr. costo bulto]]/Tabla1[[#This Row],[Cant. Bulto]] -> #DIV/0! | J38: - | L38: =K38/30 -> 0 | M38: =L38/10 -> 0
B39: =Tabla1[[#This Row],[Nombre insumo]] -> 0 | H39: =Tabla1[[#This Row],[Pr. costo bulto]]/Tabla1[[#This Row],[Cant. Bulto]] -> #DIV/0! | J39: - | L39: =K39/30 -> 0 | M39: =L39/10 -> 0
B40: =Tabla1[[#This Row],[Nombre insumo]] -> 0 | H40: =Tabla1[[#This Row],[Pr. costo bulto]]/Tabla1[[#This Row],[Cant. Bulto]] -> #DIV/0! | J40: - | L40: =K40/30 -> 0 | M40: =L40/10 -> 0
... B49: =Tabla1[[#This Row],[Nombre insumo]] -> 0 | H49: =Tabla1[[#This Row],[Pr. costo bulto]]/Tabla1[[#This Row],[Cant. Bulto]] -> #DIV/0! | J49: - | L49: =K49/30 -> 0 | M49: =L49/10 -> 0
B50: =Tabla1[[#This Row],[Nombre insumo]] -> 0 | H50: =Tabla1[[#This Row],[Pr. costo bulto]]/Tabla1[[#This Row],[Cant. Bulto]] -> #DIV/0! | J50: Total | L50: =SUM(L25:L49) -> 0 | M50: =SUM(M25:M49) -> 0
B51: =Tabla1[[#This Row],[Nombre insumo]] -> 0 | H51: =Tabla1[[#This Row],[Pr. costo bulto]]/Tabla1[[#This Row],[Cant. Bulto]] -> #DIV/0! | J51: (*) Calculado en base a 10 horas de trabajo
...

Sheet Calculadora de costos
J2: Calculadora
J3: Calcula el valor de cualquier presupuesto o producto teniendo en cuenta todos los costos ❤
J5: Insumos | K5: Tipo de insumo | L5: Costo insumo | M5: Cantidad | N5: Total costo insumo | O5: Doble faz | P5: Impresora | Q5: Costo impresión | R5: Total insumo + impresión
A6: SI | I6: EPSON L4260 | K6: =IFERROR(VLOOKUP(J6,'Insumos y gastos'!$B$13:$C$83,2,0),"") -> 0 | L6: =IFERROR(VLOOKUP(J6,Tabla1[[#All],[Nombre insumo]:[Pr. Unidad]],4,0),0) -> 0 | N6: =Tabla2[[#This Row],[Cantidad]]*Tabla2[[#This Row],[Costo insumo]] -> 0 | Q6: =IF(AND(Tabla2[[#This Row],[Tipo de insumo]]="PAPEL",Tabla2[[#This Row],[Doble faz]]="SI",Tabla2[[#This Row],[Impresora]]='Insumos y gastos'!$J$6),M6*'Insumos y gastos'!$K$15*2,IF(AND(Tabla2[[#This Row],[Tipo de insumo]]="PAPEL",Tabla2[[#This Row],[Doble faz]]="SI",Tabla2[[#This Row],[Impresora]]='Insumos y gastos'!$L$6),M6*'Insumos y gastos'!$M$15*2,IF(AND(Tabla2[[#This Row],[Tipo de insumo]]="PAPEL",Tabla2[[#This Row],[Doble faz]]="SI",Tabla2[[#This Row],[Impresora]]='Insumos y gastos'!$N$6),M6*'Insumos y gastos'!$O$15*2,IF(AND(Tabla2[[#This Row],[Tipo de insumo]]="PAPEL",Tabla2[[#This Row],[Doble faz]]="SI",Tabla2[[#This Row],[Impresora]]='Insumos y gastos'!$P$6),M6*'Insumos y gastos'!$Q$15*2,IF(AND(Tabla2[[#This Row],[Tipo de insumo]]="PAPEL",Tabla2[[#This Row],[Doble faz]]="SI",Tabla2[[#This Row],[Impresora]]='Insumos y gastos'!$R$6),M6*'Insumos y gastos'!$S$15*2,IF(AND(Tabla2[[#This Row],[Tipo de insumo]]="PAPEL",Tabla2[[#This Row],[Doble faz]]="SI",Tabla2[[#This Row],[Impresora]]='Insumos y gastos'!$T$6),M6*'Insumos y gastos'!$U$15*2,IF(AND(Tabla2[[#This Row],[Tipo de insumo]]="PAPEL",Tabla2[[#This Row],[Doble faz]]="NO",Tabla2[[#This Row],[Impresora]]='Insumos y gastos'!$J$6),M6*'Insumos y gastos'!$K$15,IF(AND(Tabla2[[#This Row],[Tipo de insumo]]="PAPEL",Tabla2[[#This Row],[Doble faz]]="NO",Tabla2[[#This Row],[Impresora]]='Insumos y gastos'!$L$6),M6*'Insumos y gastos'!$M$15,IF(AND(Tabla2[[#This Row],[Tipo de insumo]]="PAPEL",Tabla2[[#This Row],[Doble faz]]="NO",Tabla2[[#This Row],[Impresora]]='Insumos y gastos'!$N$6),M6*'Insumos y gastos'!$O$15,IF(AND(Tabla2[[#This Row],[Tipo de insumo]]="PAPEL",Tabla2[[#This Row],[Doble faz]]="NO",Tabla2[[#This Row],[Impresora]]='Insumos y gastos'!$P$6),M6*'Insumos y gastos'!$Q$15,IF(AND(Tabla2[[#This Row],[Tipo de insumo]]="PAPEL",Tabla2[[#This Row],[Doble faz]]="NO",Tabla2[[#This Row],[Impresora]]='Insumos y gastos'!$R$6),M6*'Insumos y gastos'!$S$15,IF(AND(Tabla2[[#This Row],[Tipo de insumo]]="PAPEL",Tabla2[[#This Row],[Doble faz]]="NO",Tabla2[[#This Row],[Impresora]]='Insumos y gastos'!$T$6),M6*'Insumos y gastos'!$U$15,0)))))))))))) -> 0 | R6: =Tabla2[[#This Row],[Costo impresión]]+Tabla2[[#This Row],[Total costo insumo]] -> 0
A7: NO | I7: BROTHER T420W | K7: =IFERROR(VLOOKUP(J7,'Insumos y gastos'!$B$13:$C$83,2,0),"") -> 0 | L7: =IFERROR(VLOOKUP(J7,Tabla1[[#All],[Nombre insumo]:[Pr. Unidad]],4,0),0) -> 0 | N7: =Tabla2[[#This Row],[Cantidad]]*Tabla2[[#This Row],[Costo insumo]] -> 0 | Q7: =IF(AND(Tabla2[[#This Row],[Tipo de insumo]]="PAPEL",Tabla2[[#This Row],[Doble faz]]="SI",Tabla2[[#This Row],[Impresora]]='Insumos y gastos'!$J$6),M7*'Insumos y gastos'!$K$15*2,IF(AND(Tabla2[[#This Row],[Tipo de insumo]]="PAPEL",Tabla2[[#This Row],[Doble faz]]="SI",Tabla2[[#This Row],[Impresora]]='Insumos y gastos'!$L$6),M7*'Insumos y gastos'!$M$15*2,IF(AND(Tabla2[[#This Row],[Tipo de insumo]]="PAPEL",Tabla2[[#This Row],[Doble faz]]="SI",Tabla2[[#This Row],[Impresora]]='Insumos y gastos'!$N$6),M7*'Insumos y gastos'!$O$15*2,IF(AND(Tabla2[[#This Row],[Tipo de insumo]]="PAPEL",Tabla2[[#This Row],[Doble faz]]="SI",Tabla2[[#This Row],[Impresora]]='Insumos y gastos'!$P$6),M7*'Insumos y gastos'!$Q$15*2,IF(AND(Tabla2[[#This Row],[Tipo de insumo]]="PAPEL",Tabla2[[#This Row],[Doble faz]]="SI",Tabla2[[#This Row],[Impresora]]='Insumos y gastos'!$R$6),M7*'Insumos y gastos'!$S$15*2,IF(AND(Tabla2[[#This Row],[Tipo de insumo]]="PAPEL",Tabla2[[#This Row],[Doble faz]]="SI",Tabla2[[#This Row],[Impresora]]='Insumos y gastos'!$T$6),M7*'Insumos y gastos'!$U$15*2,IF(AND(Tabla2[[#This Row],[Tipo de insumo]]="PAPEL",Tabla2[[#This Row],[Doble faz]]="NO",Tabla2[[#This Row],[Impresora]]='Insumos y gastos'!$J$6),M7*'Insumos y gastos'!$K$15,IF(AND(Tabla2[[#This Row],[Tipo de insumo]]="PAPEL",Tabla2[[#This Row],[Doble faz]]="NO",Tabla2[[#This Row],[Impresora]]='Insumos y gastos'!$L$6),M7*'Insumos y gastos'!$M$15,IF(AND(Tabla2[[#This Row],[Tipo de insumo]]="PAPEL",Tabla2[[#This Row],[Doble faz]]="NO",Tabla2[[#This Row],[Impresora]]='Insumos y gastos'!$N$6),M7*'Insumos y gastos'!$O$15,IF(AND(Tabla2[[#This Row],[Tipo de insumo]]="PAPEL",Tabla2[[#This Row],[Doble faz]]="NO",Tabla2[[#This Row],[Impresora]]='Insumos y gastos'!$P$6),M7*'Insumos y gastos'!$Q$15,IF(AND(Tabla2[[#This Row],[Tipo de insumo]]="PAPEL",Tabla2[[#This Row],[Doble faz]]="NO",Tabla2[[#This Row],[Impresora]]='Insumos y gastos'!$R$6),M7*'Insumos y gastos'!$S$15,IF(AND(Tabla2[[#This Row],[Tipo de insumo]]="PAPEL",Tabla2[[#This Row],[Doble faz]]="NO",Tabla2[[#This Row],[Impresora]]='Insumos y gastos'!$T$6),M7*'Insumos y gastos'!$U$15,0)))))))))))) -> 0 | R7: =Tabla2[[#This Row],[Costo impresión]]+Tabla2[[#This Row],[Total costo insumo]] -> 0
I8: EPSON L1250 | K8: =IFERROR(VLOOKUP(J8,'Insumos y gastos'!$B$13:$C$83,2,0),"") -> 0 | L8: =IFERROR(VLOOKUP(J8,Tabla1[[#All],[Nombre insumo]:[Pr. Unidad]],4,0),0) -> 0 | N8: =Tabla2[[#This Row],[Cantidad]]*Tabla2[[#This Row],[Costo insumo]] -> 0 | Q8: =IF(AND(Tabla2[[#This Row],[Tipo de insumo]]="PAPEL",Tabla2[[#This Row],[Doble faz]]="SI",Tabla2[[#This Row],[Impresora]]='Insumos y gastos'!$J$6),M8*'Insumos y gastos'!$K$15*2,IF(AND(Tabla2[[#This Row],[Tipo de insumo]]="PAPEL",Tabla2[[#This Row],[Doble faz]]="SI",Tabla2[[#This Row],[Impresora]]='Insumos y gastos'!$L$6),M8*'Insumos y gastos'!$M$15*2,IF(AND(Tabla2[[#This Row],[Tipo de insumo]]="PAPEL",Tabla2[[#This Row],[Doble faz]]="SI",Tabla2[[#This Row],[Impresora]]='Insumos y gastos'!$N$6),M8*'Insumos y gastos'!$O$15*2,IF(AND(Tabla2[[#This Row],[Tipo de insumo]]="PAPEL",Tabla2[[#This Row],[Doble faz]]="SI",Tabla2[[#This Row],[Impresora]]='Insumos y gastos'!$P$6),M8*'Insumos y gastos'!$Q$15*2,IF(AND(Tabla2[[#This Row],[Tipo de insumo]]="PAPEL",Tabla2[[#This Row],[Doble faz]]="SI",Tabla2[[#This Row],[Impresora]]='Insumos y gastos'!$R$6),M8*'Insumos y gastos'!$S$15*2,IF(AND(Tabla2[[#This Row],[Tipo de insumo]]="PAPEL",Tabla2[[#This Row],[Doble faz]]="SI",Tabla2[[#This Row],[Impresora]]='Insumos y gastos'!$T$6),M8*'Insumos y gastos'!$U$15*2,IF(AND(Tabla2[[#This Row],[Tipo de insumo]]="PAPEL",Tabla2[[#This Row],[Doble faz]]="NO",Tabla2[[#This Row],[Impresora]]='Insumos y gastos'!$J$6),M8*'Insumos y gastos'!$K$15,IF(AND(Tabla2[[#This Row],[Tipo de insumo]]="PAPEL",Tabla2[[#This Row],[Doble faz]]="NO",Tabla2[[#This Row],[Impresora]]='Insumos y gastos'!$L$6),M8*'Insumos y gastos'!$M$15,IF(AND(Tabla2[[#This Row],[Tipo de insumo]]="PAPEL",Tabla2[[#This Row],[Doble faz]]="NO",Tabla2[[#This Row],[Impresora]]='Insumos y gastos'!$N$6),M8*'Insumos y gastos'!$O$15,IF(AND(Tabla2[[#This Row],[Tipo de insumo]]="PAPEL",Tabla2[[#This Row],[Doble faz]]="NO",Tabla2[[#This Row],[Impresora]]='Insumos y gastos'!$P$6),M8*'Insumos y gastos'!$Q$15,IF(AND(Tabla2[[#This Row],[Tipo de insumo]]="PAPEL",Tabla2[[#This Row],[Doble faz]]="NO",Tabla2[[#This Row],[Impresora]]='Insumos y gastos'!$R$6),M8*'Insumos y gastos'!$S$15,IF(AND(Tabla2[[#This Row],[Tipo de insumo]]="PAPEL",Tabla2[[#This Row],[Doble faz]]="NO",Tabla2[[#This Row],[Impresora]]='Insumos y gastos'!$T$6),M8*'Insumos y gastos'!$U$15,0)))))))))))) -> 0 | R8: =Tabla2[[#This Row],[Costo impresión]]+Tabla2[[#This Row],[Total costo insumo]] -> 0
I9: EPSON L1250 SUBLIMACION | K9: =IFERROR(VLOOKUP(J9,'Insumos y gastos'!$B$13:$C$83,2,0),"") -> 0 | L9: =IFERROR(VLOOKUP(J9,Tabla1[[#All],[Nombre insumo]:[Pr. Unidad]],4,0),0) -> 0 | N9: =Tabla2[[#This Row],[Cantidad]]*Tabla2[[#This Row],[Costo insumo]] -> 0 | Q9: =IF(AND(Tabla2[[#This Row],[Tipo de insumo]]="PAPEL",Tabla2[[#This Row],[Doble faz]]="SI",Tabla2[[#This Row],[Impresora]]='Insumos y gastos'!$J$6),M9*'Insumos y gastos'!$K$15*2,IF(AND(Tabla2[[#This Row],[Tipo de insumo]]="PAPEL",Tabla2[[#This Row],[Doble faz]]="SI",Tabla2[[#This Row],[Impresora]]='Insumos y gastos'!$L$6),M9*'Insumos y gastos'!$M$15*2,IF(AND(Tabla2[[#This Row],[Tipo de insumo]]="PAPEL",Tabla2[[#This Row],[Doble faz]]="SI",Tabla2[[#This Row],[Impresora]]='Insumos y gastos'!$N$6),M9*'Insumos y gastos'!$O$15*2,IF(AND(Tabla2[[#This Row],[Tipo de insumo]]="PAPEL",Tabla2[[#This Row],[Doble faz]]="SI",Tabla2[[#This Row],[Impresora]]='Insumos y gastos'!$P$6),M9*'Insumos y gastos'!$Q$15*2,IF(AND(Tabla2[[#This Row],[Tipo de insumo]]="PAPEL",Tabla2[[#This Row],[Doble faz]]="SI",Tabla2[[#This Row],[Impresora]]='Insumos y gastos'!$R$6),M9*'Insumos y gastos'!$S$15*2,IF(AND(Tabla2[[#This Row],[Tipo de insumo]]="PAPEL",Tabla2[[#This Row],[Doble faz]]="SI",Tabla2[[#This Row],[Impresora]]='Insumos y gastos'!$T$6),M9*'Insumos y gastos'!$U$15*2,IF(AND(Tabla2[[#This Row],[Tipo de insumo]]="PAPEL",Tabla2[[#This Row],[Doble faz]]="NO",Tabla2[[#This Row],[Impresora]]='Insumos y gastos'!$J$6),M9*'Insumos y gastos'!$K$15,IF(AND(Tabla2[[#This Row],[Tipo de insumo]]="PAPEL",Tabla2[[#This Row],[Doble faz]]="NO",Tabla2[[#This Row],[Impresora]]='Insumos y gastos'!$L$6),M9*'Insumos y gastos'!$M$15,IF(AND(Tabla2[[#This Row],[Tipo de insumo]]="PAPEL",Tabla2[[#This Row],[Doble faz]]="NO",Tabla2[[#This Row],[Impresora]]='Insumos y gastos'!$N$6),M9*'Insumos y gastos'!$O$15,IF(AND(Tabla2[[#This Row],[Tipo de insumo]]="PAPEL",Tabla2[[#This Row],[Doble faz]]="NO",Tabla2[[#This Row],[Impresora]]='Insumos y gastos'!$P$6),M9*'Insumos y gastos'!$Q$15,IF(AND(Tabla2[[#This Row],[Tipo de insumo]]="PAPEL",Tabla2[[#This Row],[Doble faz]]="NO",Tabla2[[#This Row],[Impresora]]='Insumos y gastos'!$R$6),M9*'Insumos y gastos'!$S$15,IF(AND(Tabla2[[#This Row],[Tipo de insumo]]="PAPEL",Tabla2[[#This Row],[Doble faz]]="NO",Tabla2[[#This Row],[Impresora]]='Insumos y gastos'!$T$6),M9*'Insumos y gastos'!$U$15,0)))))))))))) -> 0 | R9: =Tabla2[[#This Row],[Costo impresión]]+Tabla2[[#This Row],[Total costo insumo]] -> 0
I10: HP M1111W | K10: =IFERROR(VLOOKUP(J10,'Insumos y gastos'!$B$13:$C$83,2,0),"") -> 0 | L10: =IFERROR(VLOOKUP(J10,Tabla1[[#All],[Nombre insumo]:[Pr. Unidad]],4,0),0) -> 0 | N10: =Tabla2[[#This Row],[Cantidad]]*Tabla2[[#This Row],[Costo insumo]] -> 0 | Q10: =IF(AND(Tabla2[[#This Row],[Tipo de insumo]]="PAPEL",Tabla2[[#This Row],[Doble faz]]="SI",Tabla2[[#This Row],[Impresora]]='Insumos y gastos'!$J$6),M10*'Insumos y gastos'!$K$15*2,IF(AND(Tabla2[[#This Row],[Tipo de insumo]]="PAPEL",Tabla2[[#This Row],[Doble faz]]="SI",Tabla2[[#This Row],[Impresora]]='Insumos y gastos'!$L$6),M10*'Insumos y gastos'!$M$15*2,IF(AND(Tabla2[[#This Row],[Tipo de insumo]]="PAPEL",Tabla2[[#This Row],[Doble faz]]="SI",Tabla2[[#This Row],[Impresora]]='Insumos y gastos'!$N$6),M10*'Insumos y gastos'!$O$15*2,IF(AND(Tabla2[[#This Row],[Tipo de insumo]]="PAPEL",Tabla2[[#This Row],[Doble faz]]="SI",Tabla2[[#This Row],[Impresora]]='Insumos y gastos'!$P$6),M10*'Insumos y gastos'!$Q$15*2,IF(AND(Tabla2[[#This Row],[Tipo de insumo]]="PAPEL",Tabla2[[#This Row],[Doble faz]]="SI",Tabla2[[#This Row],[Impresora]]='Insumos y gastos'!$R$6),M10*'Insumos y gastos'!$S$15*2,IF(AND(Tabla2[[#This Row],[Tipo de insumo]]="PAPEL",Tabla2[[#This Row],[Doble faz]]="SI",Tabla2[[#This Row],[Impresora]]='Insumos y gastos'!$T$6),M10*'Insumos y gastos'!$U$15*2,IF(AND(Tabla2[[#This Row],[Tipo de insumo]]="PAPEL",Tabla2[[#This Row],[Doble faz]]="NO",Tabla2[[#This Row],[Impresora]]='Insumos y gastos'!$J$6),M10*'Insumos y gastos'!$K$15,IF(AND(Tabla2[[#This Row],[Tipo de insumo]]="PAPEL",Tabla2[[#This Row],[Doble faz]]="NO",Tabla2[[#This Row],[Impresora]]='Insumos y gastos'!$L$6),M10*'Insumos y gastos'!$M$15,IF(AND(Tabla2[[#This Row],[Tipo de insumo]]="PAPEL",Tabla2[[#This Row],[Doble faz]]="NO",Tabla2[[#This Row],[Impresora]]='Insumos y gastos'!$N$6),M10*'Insumos y gastos'!$O$15,IF(AND(Tabla2[[#This Row],[Tipo de insumo]]="PAPEL",Tabla2[[#This Row],[Doble faz]]="NO",Tabla2[[#This Row],[Impresora]]='Insumos y gastos'!$P$6),M10*'Insumos y gastos'!$Q$15,IF(AND(Tabla2[[#This Row],[Tipo de insumo]]="PAPEL",Tabla2[[#This Row],[Doble faz]]="NO",Tabla2[[#This Row],[Impresora]]='Insumos y gastos'!$R$6),M10*'Insumos y gastos'!$S$15,IF(AND(Tabla2[[#This Row],[Tipo de insumo]]="PAPEL",Tabla2[[#This Row],[Doble faz]]="NO",Tabla2[[#This Row],[Impresora]]='Insumos y gastos'!$T$6),M10*'Insumos y gastos'!$U$15,0)))))))))))) -> 0 | R10: =Tabla2[[#This Row],[Costo impresión]]+Tabla2[[#This Row],[Total costo insumo]] -> 0
K11: =IFERROR(VLOOKUP(J11,'Insumos y gastos'!$B$13:$C$83,2,0),"") -> 0 | L11: =IFERROR(VLOOKUP(J11,Tabla1[[#All],[Nombre insumo]:[Pr. Unidad]],4,0),0) -> 0 | N11: =Tabla2[[#This Row],[Cantidad]]*Tabla2[[#This Row],[Costo insumo]] -> 0 | Q11: =IF(AND(Tabla2[[#This Row],[Tipo de insumo]]="PAPEL",Tabla2[[#This Row],[Doble faz]]="SI",Tabla2[[#This Row],[Impresora]]='Insumos y gastos'!$J$6),M11*'Insumos y gastos'!$K$15*2,IF(AND(Tabla2[[#This Row],[Tipo de insumo]]="PAPEL",Tabla2[[#This Row],[Doble faz]]="SI",Tabla2[[#This Row],[Impresora]]='Insumos y gastos'!$L$6),M11*'Insumos y gastos'!$M$15*2,IF(AND(Tabla2[[#This Row],[Tipo de insumo]]="PAPEL",Tabla2[[#This Row],[Doble faz]]="SI",Tabla2[[#This Row],[Impresora]]='Insumos y gastos'!$N$6),M11*'Insumos y gastos'!$O$15*2,IF(AND(Tabla2[[#This Row],[Tipo de insumo]]="PAPEL",Tabla2[[#This Row],[Doble faz]]="SI",Tabla2[[#This Row],[Impresora]]='Insumos y gastos'!$P$6),M11*'Insumos y gastos'!$Q$15*2,IF(AND(Tabla2[[#This Row],[Tipo de insumo]]="PAPEL",Tabla2[[#This Row],[Doble faz]]="SI",Tabla2[[#This Row],[Impresora]]='Insumos y gastos'!$R$6),M11*'Insumos y gastos'!$S$15*2,IF(AND(Tabla2[[#This Row],[Tipo de insumo]]="PAPEL",Tabla2[[#This Row],[Doble faz]]="SI",Tabla2[[#This Row],[Impresora]]='Insumos y gastos'!$T$6),M11*'Insumos y gastos'!$U$15*2,IF(AND(Tabla2[[#This Row],[Tipo de insumo]]="PAPEL",Tabla2[[#This Row],[Doble faz]]="NO",Tabla2[[#This Row],[Impresora]]='Insumos y gastos'!$J$6),M11*'Insumos y gastos'!$K$15,IF(AND(Tabla2[[#This Row],[Tipo de insumo]]="PAPEL",Tabla2[[#This Row],[Doble faz]]="NO",Tabla2[[#This Row],[Impresora]]='Insumos y gastos'!$L$6),M11*'Insumos y gastos'!$M$15,IF(AND(Tabla2[[#This Row],[Tipo de insumo]]="PAPEL",Tabla2[[#This Row],[Doble faz]]="NO",Tabla2[[#This Row],[Impresora]]='Insumos y gastos'!$N$6),M11*'Insumos y gastos'!$O$15,IF(AND(Tabla2[[#This Row],[Tipo de insumo]]="PAPEL",Tabla2[[#This Row],[Doble faz]]="NO",Tabla2[[#This Row],[Impresora]]='Insumos y gastos'!$P$6),M11*'Insumos y gastos'!$Q$15,IF(AND(Tabla2[[#This Row],[Tipo de insumo]]="PAPEL",Tabla2[[#This Row],[Doble faz]]="NO",Tabla2[[#This Row],[Impresora]]='Insumos y gastos'!$R$6),M11*'Insumos y gastos'!$S$15,IF(AND(Tabla2[[#This Row],[Tipo de insumo]]="PAPEL",Tabla2[[#This Row],[Doble faz]]="NO",Tabla2[[#This Row],[Impresora]]='Insumos y gastos'!$T$6),M11*'Insumos y gastos'!$U$15,0)))))))))))) -> 0 | R11: =Tabla2[[#This Row],[Costo impresión]]+Tabla2[[#This Row],[Total costo insumo]] -> 0
K12: =IFERROR(VLOOKUP(J12,'Insumos y gastos'!$B$13:$C$83,2,0),"") -> 0 | L12: =IFERROR(VLOOKUP(J12,Tabla1[[#All],[Nombre insumo]:[Pr. Unidad]],4,0),0) -> 0 | N12: =Tabla2[[#This Row],[Cantidad]]*Tabla2[[#This Row],[Costo insumo]] -> 0 | Q12: =IF(AND(Tabla2[[#This Row],[Tipo de insumo]]="PAPEL",Tabla2[[#This Row],[Doble faz]]="SI",Tabla2[[#This Row],[Impresora]]='Insumos y gastos'!$J$6),M12*'Insumos y gastos'!$K$15*2,IF(AND(Tabla2[[#This Row],[Tipo de insumo]]="PAPEL",Tabla2[[#This Row],[Doble faz]]="SI",Tabla2[[#This Row],[Impresora]]='Insumos y gastos'!$L$6),M12*'Insumos y gastos'!$M$15*2,IF(AND(Tabla2[[#This Row],[Tipo de insumo]]="PAPEL",Tabla2[[#This Row],[Doble faz]]="SI",Tabla2[[#This Row],[Impresora]]='Insumos y gastos'!$N$6),M12*'Insumos y gastos'!$O$15*2,IF(AND(Tabla2[[#This Row],[Tipo de insumo]]="PAPEL",Tabla2[[#This Row],[Doble faz]]="SI",Tabla2[[#This Row],[Impresora]]='Insumos y gastos'!$P$6),M12*'Insumos y gastos'!$Q$15*2,IF(AND(Tabla2[[#This Row],[Tipo de insumo]]="PAPEL",Tabla2[[#This Row],[Doble faz]]="SI",Tabla2[[#This Row],[Impresora]]='Insumos y gastos'!$R$6),M12*'Insumos y gastos'!$S$15*2,IF(AND(Tabla2[[#This Row],[Tipo de insumo]]="PAPEL",Tabla2[[#This Row],[Doble faz]]="SI",Tabla2[[#This Row],[Impresora]]='Insumos y gastos'!$T$6),M12*'Insumos y gastos'!$U$15*2,IF(AND(Tabla2[[#This Row],[Tipo de insumo]]="PAPEL",Tabla2[[#This Row],[Doble faz]]="NO",Tabla2[[#This Row],[Impresora]]='Insumos y gastos'!$J$6),M12*'Insumos y gastos'!$K$15,IF(AND(Tabla2[[#This Row],[Tipo de insumo]]="PAPEL",Tabla2[[#This Row],[Doble faz]]="NO",Tabla2[[#This Row],[Impresora]]='Insumos y gastos'!$L$6),M12*'Insumos y gastos'!$M$15,IF(AND(Tabla2[[#This Row],[Tipo de insumo]]="PAPEL",Tabla2[[#This Row],[Doble faz]]="NO",Tabla2[[#This Row],[Impresora]]='Insumos y gastos'!$N$6),M12*'Insumos y gastos'!$O$15,IF(AND(Tabla2[[#This Row],[Tipo de insumo]]="PAPEL",Tabla2[[#This Row],[Doble faz]]="NO",Tabla2[[#This Row],[Impresora]]='Insumos y gastos'!$P$6),M12*'Insumos y gastos'!$Q$15,IF(AND(Tabla2[[#This Row],[Tipo de insumo]]="PAPEL",Tabla2[[#This Row],[Doble faz]]="NO",Tabla2[[#This Row],[Impresora]]='Insumos y gastos'!$R$6),M12*'Insumos y gastos'!$S$15,IF(AND(Tabla2[[#This Row],[Tipo de insumo]]="PAPEL",Tabla2[[#This Row],[Doble faz]]="NO",Tabla2[[#This Row],[Impresora]]='Insumos y gastos'!$T$6),M12*'Insumos y gastos'!$U$15,0)))))))))))) -> 0 | R12: =Tabla2[[#This Row],[Costo impresión]]+Tabla2[[#This Row],[Total costo insumo]] -> 0
K13: =IFERROR(VLOOKUP(J13,'Insumos y gastos'!$B$13:$C$83,2,0),"") -> 0 | L13: =IFERROR(VLOOKUP(J13,Tabla1[[#All],[Nombre insumo]:[Pr. Unidad]],4,0),0) -> 0 | N13: =Tabla2[[#This Row],[Cantidad]]*Tabla2[[#This Row],[Costo insumo]] -> 0 | Q13: =IF(AND(Tabla2[[#This Row],[Tipo de insumo]]="PAPEL",Tabla2[[#This Row],[Doble faz]]="SI",Tabla2[[#This Row],[Impresora]]='Insumos y gastos'!$J$6),M13*'Insumos y gastos'!$K$15*2,IF(AND(Tabla2[[#This Row],[Tipo de insumo]]="PAPEL",Tabla2[[#This Row],[Doble faz]]="SI",Tabla2[[#This Row],[Impresora]]='Insumos y gastos'!$L$6),M13*'Insumos y gastos'!$M$15*2,IF(AND(Tabla2[[#This Row],[Tipo de insumo]]="PAPEL",Tabla2[[#This Row],[Doble faz]]="SI",Tabla2[[#This Row],[Impresora]]='Insumos y gastos'!$N$6),M13*'Insumos y gastos'!$O$15*2,IF(AND(Tabla2[[#This Row],[Tipo de insumo]]="PAPEL",Tabla2[[#This Row],[Doble faz]]="SI",Tabla2[[#This Row],[Impresora]]='Insumos y gastos'!$P$6),M13*'Insumos y gastos'!$Q$15*2,IF(AND(Tabla2[[#This Row],[Tipo de insumo]]="PAPEL",Tabla2[[#This Row],[Doble faz]]="SI",Tabla2[[#This Row],[Impresora]]='Insumos y gastos'!$R$6),M13*'Insumos y gastos'!$S$15*2,IF(AND(Tabla2[[#This Row],[Tipo de insumo]]="PAPEL",Tabla2[[#This Row],[Doble faz]]="SI",Tabla2[[#This Row],[Impresora]]='Insumos y gastos'!$T$6),M13*'Insumos y gastos'!$U$15*2,IF(AND(Tabla2[[#This Row],[Tipo de insumo]]="PAPEL",Tabla2[[#This Row],[Doble faz]]="NO",Tabla2[[#This Row],[Impresora]]='Insumos y gastos'!$J$6),M13*'Insumos y gastos'!$K$15,IF(AND(Tabla2[[#This Row],[Tipo de insumo]]="PAPEL",Tabla2[[#This Row],[Doble faz]]="NO",Tabla2[[#This Row],[Impresora]]='Insumos y gastos'!$L$6),M13*'Insumos y gastos'!$M$15,IF(AND(Tabla2[[#This Row],[Tipo de insumo]]="PAPEL",Tabla2[[#This Row],[Doble faz]]="NO",Tabla2[[#This Row],[Impresora]]='Insumos y gastos'!$N$6),M13*'Insumos y gastos'!$O$15,IF(AND(Tabla2[[#This Row],[Tipo de insumo]]="PAPEL",Tabla2[[#This Row],[Doble faz]]="NO",Tabla2[[#This Row],[Impresora]]='Insumos y gastos'!$P$6),M13*'Insumos y gastos'!$Q$15,IF(AND(Tabla2[[#This Row],[Tipo de insumo]]="PAPEL",Tabla2[[#This Row],[Doble faz]]="NO",Tabla2[[#This Row],[Impresora]]='Insumos y gastos'!$R$6),M13*'Insumos y gastos'!$S$15,IF(AND(Tabla2[[#This Row],[Tipo de insumo]]="PAPEL",Tabla2[[#This Row],[Doble faz]]="NO",Tabla2[[#This Row],[Impresora]]='Insumos y gastos'!$T$6),M13*'Insumos y gastos'!$U$15,0)))))))))))) -> 0 | R13: =Tabla2[[#This Row],[Costo impresión]]+Tabla2[[#This Row],[Total costo insumo]] -> 0
K14: =IFERROR(VLOOKUP(J14,'Insumos y gastos'!$B$13:$C$83,2,0),"") -> 0 | L14: =IFERROR(VLOOKUP(J14,Tabla1[[#All],[Nombre insumo]:[Pr. Unidad]],4,0),0) -> 0 | N14: =Tabla2[[#This Row],[Cantidad]]*Tabla2[[#This Row],[Costo insumo]] -> 0 | Q14: =IF(AND(Tabla2[[#This Row],[Tipo de insumo]]="PAPEL",Tabla2[[#This Row],[Doble faz]]="SI",Tabla2[[#This Row],[Impresora]]='Insumos y gastos'!$J$6),M14*'Insumos y gastos'!$K$15*2,IF(AND(Tabla2[[#This Row],[Tipo de insumo]]="PAPEL",Tabla2[[#This Row],[Doble faz]]="SI",Tabla2[[#This Row],[Impresora]]='Insumos y gastos'!$L$6),M14*'Insumos y gastos'!$M$15*2,IF(AND(Tabla2[[#This Row],[Tipo de insumo]]="PAPEL",Tabla2[[#This Row],[Doble faz]]="SI",Tabla2[[#This Row],[Impresora]]='Insumos y gastos'!$N$6),M14*'Insumos y gastos'!$O$15*2,IF(AND(Tabla2[[#This Row],[Tipo de insumo]]="PAPEL",Tabla2[[#This Row],[Doble faz]]="SI",Tabla2[[#This Row],[Impresora]]='Insumos y gastos'!$P$6),M14*'Insumos y gastos'!$Q$15*2,IF(AND(Tabla2[[#This Row],[Tipo de insumo]]="PAPEL",Tabla2[[#This Row],[Doble faz]]="SI",Tabla2[[#This Row],[Impresora]]='Insumos y gastos'!$R$6),M14*'Insumos y gastos'!$S$15*2,IF(AND(Tabla2[[#This Row],[Tipo de insumo]]="PAPEL",Tabla2[[#This Row],[Doble faz]]="SI",Tabla2[[#This Row],[Impresora]]='Insumos y gastos'!$T$6),M14*'Insumos y gastos'!$U$15*2,IF(AND(Tabla2[[#This Row],[Tipo de insumo]]="PAPEL",Tabla2[[#This Row],[Doble faz]]="NO",Tabla2[[#This Row],[Impresora]]='Insumos y gastos'!$J$6),M14*'Insumos y gastos'!$K$15,IF(AND(Tabla2[[#This Row],[Tipo de insumo]]="PAPEL",Tabla2[[#This Row],[Doble faz]]="NO",Tabla2[[#This Row],[Impresora]]='Insumos y gastos'!$L$6),M14*'Insumos y gastos'!$M$15,IF(AND(Tabla2[[#This Row],[Tipo de insumo]]="PAPEL",Tabla2[[#This Row],[Doble faz]]="NO",Tabla2[[#This Row],[Impresora]]='Insumos y gastos'!$N$6),M14*'Insumos y gastos'!$O$15,IF(AND(Tabla2[[#This Row],[Tipo de insumo]]="PAPEL",Tabla2[[#This Row],[Doble faz]]="NO",Tabla2[[#This Row],[Impresora]]='Insumos y gastos'!$P$6),M14*'Insumos y gastos'!$Q$15,IF(AND(Tabla2[[#This Row],[Tipo de insumo]]="PAPEL",Tabla2[[#This Row],[Doble faz]]="NO",Tabla2[[#This Row],[Impresora]]='Insumos y gastos'!$R$6),M14*'Insumos y gastos'!$S$15,IF(AND(Tabla2[[#This Row],[Tipo de insumo]]="PAPEL",Tabla2[[#This Row],[Doble faz]]="NO",Tabla2[[#This Row],[Impresora]]='Insumos y gastos'!$T$6),M14*'Insumos y gastos'!$U$15,0)))))))))))) -> 0 | R14: =Tabla2[[#This Row],[Costo impresión]]+Tabla2[[#This Row],[Total costo insumo]] -> 0
K15: =IFERROR(VLOOKUP(J15,'Insumos y gastos'!$B$13:$C$83,2,0),"") -> 0 | L15: =IFERROR(VLOOKUP(J15,Tabla1[[#All],[Nombre insumo]:[Pr. Unidad]],4,0),0) -> 0 | N15: =Tabla2[[#This Row],[Cantidad]]*Tabla2[[#This Row],[Costo insumo]] -> 0 | Q15: =IF(AND(Tabla2[[#This Row],[Tipo de insumo]]="PAPEL",Tabla2[[#This Row],[Doble faz]]="SI",Tabla2[[#This Row],[Impresora]]='Insumos y gastos'!$J$6),M15*'Insumos y gastos'!$K$15*2,IF(AND(Tabla2[[#This Row],[Tipo de insumo]]="PAPEL",Tabla2[[#This Row],[Doble faz]]="SI",Tabla2[[#This Row],[Impresora]]='Insumos y gastos'!$L$6),M15*'Insumos y gastos'!$M$15*2,IF(AND(Tabla2[[#This Row],[Tipo de insumo]]="PAPEL",Tabla2[[#This Row],[Doble faz]]="SI",Tabla2[[#This Row],[Impresora]]='Insumos y gastos'!$N$6),M15*'Insumos y gastos'!$O$15*2,IF(AND(Tabla2[[#This Row],[Tipo de insumo]]="PAPEL",Tabla2[[#This Row],[Doble faz]]="SI",Tabla2[[#This Row],[Impresora]]='Insumos y gastos'!$P$6),M15*'Insumos y gastos'!$Q$15*2,IF(AND(Tabla2[[#This Row],[Tipo de insumo]]="PAPEL",Tabla2[[#This Row],[Doble faz]]="SI",Tabla2[[#This Row],[Impresora]]='Insumos y gastos'!$R$6),M15*'Insumos y gastos'!$S$15*2,IF(AND(Tabla2[[#This Row],[Tipo de insumo]]="PAPEL",Tabla2[[#This Row],[Doble faz]]="SI",Tabla2[[#This Row],[Impresora]]='Insumos y gastos'!$T$6),M15*'Insumos y gastos'!$U$15*2,IF(AND(Tabla2[[#This Row],[Tipo de insumo]]="PAPEL",Tabla2[[#This Row],[Doble faz]]="NO",Tabla2[[#This Row],[Impresora]]='Insumos y gastos'!$J$6),M15*'Insumos y gastos'!$K$15,IF(AND(Tabla2[[#This Row],[Tipo de insumo]]="PAPEL",Tabla2[[#This Row],[Doble faz]]="NO",Tabla2[[#This Row],[Impresora]]='Insumos y gastos'!$L$6),M15*'Insumos y gastos'!$M$15,IF(AND(Tabla2[[#This Row],[Tipo de insumo]]="PAPEL",Tabla2[[#This Row],[Doble faz]]="NO",Tabla2[[#This Row],[Impresora]]='Insumos y gastos'!$N$6),M15*'Insumos y gastos'!$O$15,IF(AND(Tabla2[[#This Row],[Tipo de insumo]]="PAPEL",Tabla2[[#This Row],[Doble faz]]="NO",Tabla2[[#This Row],[Impresora]]='Insumos y gastos'!$P$6),M15*'Insumos y gastos'!$Q$15,IF(AND(Tabla2[[#This Row],[Tipo de insumo]]="PAPEL",Tabla2[[#This Row],[Doble faz]]="NO",Tabla2[[#This Row],[Impresora]]='Insumos y gastos'!$R$6),M15*'Insumos y gastos'!$S$15,IF(AND(Tabla2[[#This Row],[Tipo de insumo]]="PAPEL",Tabla2[[#This Row],[Doble faz]]="NO",Tabla2[[#This Row],[Impresora]]='Insumos y gastos'!$T$6),M15*'Insumos y gastos'!$U$15,0)))))))))))) -> 0 | R15: =Tabla2[[#This Row],[Costo impresión]]+Tabla2[[#This Row],[Total costo insumo]] -> 0
K16: =IFERROR(VLOOKUP(J16,'Insumos y gastos'!$B$13:$C$83,2,0),"") -> 0 | L16: =IFERROR(VLOOKUP(J16,Tabla1[[#All],[Nombre insumo]:[Pr. Unidad]],4,0),0) -> 0 | N16: =Tabla2[[#This Row],[Cantidad]]*Tabla2[[#This Row],[Costo insumo]] -> 0 | Q16: =IF(AND(Tabla2[[#This Row],[Tipo de insumo]]="PAPEL",Tabla2[[#This Row],[Doble faz]]="SI",Tabla2[[#This Row],[Impresora]]='Insumos y gastos'!$J$6),M16*'Insumos y gastos'!$K$15*2,IF(AND(Tabla2[[#This Row],[Tipo de insumo]]="PAPEL",Tabla2[[#This Row],[Doble faz]]="SI",Tabla2[[#This Row],[Impresora]]='Insumos y gastos'!$L$6),M16*'Insumos y gastos'!$M$15*2,IF(AND(Tabla2[[#This Row],[Tipo de insumo]]="PAPEL",Tabla2[[#This Row],[Doble faz]]="SI",Tabla2[[#This Row],[Impresora]]='Insumos y gastos'!$N$6),M16*'Insumos y gastos'!$O$15*2,IF(AND(Tabla2[[#This Row],[Tipo de insumo]]="PAPEL",Tabla2[[#This Row],[Doble faz]]="SI",Tabla2[[#This Row],[Impresora]]='Insumos y gastos'!$P$6),M16*'Insumos y gastos'!$Q$15*2,IF(AND(Tabla2[[#This Row],[Tipo de insumo]]="PAPEL",Tabla2[[#This Row],[Doble faz]]="SI",Tabla2[[#This Row],[Impresora]]='Insumos y gastos'!$R$6),M16*'Insumos y gastos'!$S$15*2,IF(AND(Tabla2[[#This Row],[Tipo de insumo]]="PAPEL",Tabla2[[#This Row],[Doble faz]]="SI",Tabla2[[#This Row],[Impresora]]='Insumos y gastos'!$T$6),M16*'Insumos y gastos'!$U$15*2,IF(AND(Tabla2[[#This Row],[Tipo de insumo]]="PAPEL",Tabla2[[#This Row],[Doble faz]]="NO",Tabla2[[#This Row],[Impresora]]='Insumos y gastos'!$J$6),M16*'Insumos y gastos'!$K$15,IF(AND(Tabla2[[#This Row],[Tipo de insumo]]="PAPEL",Tabla2[[#This Row],[Doble faz]]="NO",Tabla2[[#This Row],[Impresora]]='Insumos y gastos'!$L$6),M16*'Insumos y gastos'!$M$15,IF(AND(Tabla2[[#This Row],[Tipo de insumo]]="PAPEL",Tabla2[[#This Row],[Doble faz]]="NO",Tabla2[[#This Row],[Impresora]]='Insumos y gastos'!$N$6),M16*'Insumos y gastos'!$O$15,IF(AND(Tabla2[[#This Row],[Tipo de insumo]]="PAPEL",Tabla2[[#This Row],[Doble faz]]="NO",Tabla2[[#This Row],[Impresora]]='Insumos y gastos'!$P$6),M16*'Insumos y gastos'!$Q$15,IF(AND(Tabla2[[#This Row],[Tipo de insumo]]="PAPEL",Tabla2[[#This Row],[Doble faz]]="NO",Tabla2[[#This Row],[Impresora]]='Insumos y gastos'!$R$6),M16*'Insumos y gastos'!$S$15,IF(AND(Tabla2[[#This Row],[Tipo de insumo]]="PAPEL",Tabla2[[#This Row],[Doble faz]]="NO",Tabla2[[#This Row],[Impresora]]='Insumos y gastos'!$T$6),M16*'Insumos y gastos'!$U$15,0)))))))))))) -> 0 | R16: =Tabla2[[#This Row],[Costo impresión]]+Tabla2[[#This Row],[Total costo insumo]] -> 0
K17: =IFERROR(VLOOKUP(J17,'Insumos y gastos'!$B$13:$C$83,2,0),"") -> 0 | L17: =IFERROR(VLOOKUP(J17,Tabla1[[#All],[Nombre insumo]:[Pr. Unidad]],4,0),0) -> 0 | N17: =Tabla2[[#This Row],[Cantidad]]*Tabla2[[#This Row],[Costo insumo]] -> 0 | Q17: =IF(AND(Tabla2[[#This Row],[Tipo de insumo]]="PAPEL",Tabla2[[#This Row],[Doble faz]]="SI",Tabla2[[#This Row],[Impresora]]='Insumos y gastos'!$J$6),M17*'Insumos y gastos'!$K$15*2,IF(AND(Tabla2[[#This Row],[Tipo de insumo]]="PAPEL",Tabla2[[#This Row],[Doble faz]]="SI",Tabla2[[#This Row],[Impresora]]='Insumos y gastos'!$L$6),M17*'Insumos y gastos'!$M$15*2,IF(AND(Tabla2[[#This Row],[Tipo de insumo]]="PAPEL",Tabla2[[#This Row],[Doble faz]]="SI",Tabla2[[#This Row],[Impresora]]='Insumos y gastos'!$N$6),M17*'Insumos y gastos'!$O$15*2,IF(AND(Tabla2[[#This Row],[Tipo de insumo]]="PAPEL",Tabla2[[#This Row],[Doble faz]]="SI",Tabla2[[#This Row],[Impresora]]='Insumos y gastos'!$P$6),M17*'Insumos y gastos'!$Q$15*2,IF(AND(Tabla2[[#This Row],[Tipo de insumo]]="PAPEL",Tabla2[[#This Row],[Doble faz]]="SI",Tabla2[[#This Row],[Impresora]]='Insumos y gastos'!$R$6),M17*'Insumos y gastos'!$S$15*2,IF(AND(Tabla2[[#This Row],[Tipo de insumo]]="PAPEL",Tabla2[[#This Row],[Doble faz]]="SI",Tabla2[[#This Row],[Impresora]]='Insumos y gastos'!$T$6),M17*'Insumos y gastos'!$U$15*2,IF(AND(Tabla2[[#This Row],[Tipo de insumo]]="PAPEL",Tabla2[[#This Row],[Doble faz]]="NO",Tabla2[[#This Row],[Impresora]]='Insumos y gastos'!$J$6),M17*'Insumos y gastos'!$K$15,IF(AND(Tabla2[[#This Row],[Tipo de insumo]]="PAPEL",Tabla2[[#This Row],[Doble faz]]="NO",Tabla2[[#This Row],[Impresora]]='Insumos y gastos'!$L$6),M17*'Insumos y gastos'!$M$15,IF(AND(Tabla2[[#This Row],[Tipo de insumo]]="PAPEL",Tabla2[[#This Row],[Doble faz]]="NO",Tabla2[[#This Row],[Impresora]]='Insumos y gastos'!$N$6),M17*'Insumos y gastos'!$O$15,IF(AND(Tabla2[[#This Row],[Tipo de insumo]]="PAPEL",Tabla2[[#This Row],[Doble faz]]="NO",Tabla2[[#This Row],[Impresora]]='Insumos y gastos'!$P$6),M17*'Insumos y gastos'!$Q$15,IF(AND(Tabla2[[#This Row],[Tipo de insumo]]="PAPEL",Tabla2[[#This Row],[Doble faz]]="NO",Tabla2[[#This Row],[Impresora]]='Insumos y gastos'!$R$6),M17*'Insumos y gastos'!$S$15,IF(AND(Tabla2[[#This Row],[Tipo de insumo]]="PAPEL",Tabla2[[#This Row],[Doble faz]]="NO",Tabla2[[#This Row],[Impresora]]='Insumos y gastos'!$T$6),M17*'Insumos y gastos'!$U$15,0)))))))))))) -> 0 | R17: =Tabla2[[#This Row],[Costo impresión]]+Tabla2[[#This Row],[Total costo insumo]] -> 0
K18: =IFERROR(VLOOKUP(J18,'Insumos y gastos'!$B$13:$C$83,2,0),"") -> 0 | L18: =IFERROR(VLOOKUP(J18,Tabla1[[#All],[Nombre insumo]:[Pr. Unidad]],4,0),0) -> 0 | N18: =Tabla2[[#This Row],[Cantidad]]*Tabla2[[#This Row],[Costo insumo]] -> 0 | Q18: =IF(AND(Tabla2[[#This Row],[Tipo de insumo]]="PAPEL",Tabla2[[#This Row],[Doble faz]]="SI",Tabla2[[#This Row],[Impresora]]='Insumos y gastos'!$J$6),M18*'Insumos y gastos'!$K$15*2,IF(AND(Tabla2[[#This Row],[Tipo de insumo]]="PAPEL",Tabla2[[#This Row],[Doble faz]]="SI",Tabla2[[#This Row],[Impresora]]='Insumos y gastos'!$L$6),M18*'Insumos y gastos'!$M$15*2,IF(AND(Tabla2[[#This Row],[Tipo de insumo]]="PAPEL",Tabla2[[#This Row],[Doble faz]]="SI",Tabla2[[#This Row],[Impresora]]='Insumos y gastos'!$N$6),M18*'Insumos y gastos'!$O$15*2,IF(AND(Tabla2[[#This Row],[Tipo de insumo]]="PAPEL",Tabla2[[#This Row],[Doble faz]]="SI",Tabla2[[#This Row],[Impresora]]='Insumos y gastos'!$P$6),M18*'Insumos y gastos'!$Q$15*2,IF(AND(Tabla2[[#This Row],[Tipo de insumo]]="PAPEL",Tabla2[[#This Row],[Doble faz]]="SI",Tabla2[[#This Row],[Impresora]]='Insumos y gastos'!$R$6),M18*'Insumos y gastos'!$S$15*2,IF(AND(Tabla2[[#This Row],[Tipo de insumo]]="PAPEL",Tabla2[[#This Row],[Doble faz]]="SI",Tabla2[[#This Row],[Impresora]]='Insumos y gastos'!$T$6),M18*'Insumos y gastos'!$U$15*2,IF(AND(Tabla2[[#This Row],[Tipo de insumo]]="PAPEL",Tabla2[[#This Row],[Doble faz]]="NO",Tabla2[[#This Row],[Impresora]]='Insumos y gastos'!$J$6),M18*'Insumos y gastos'!$K$15,IF(AND(Tabla2[[#This Row],[Tipo de insumo]]="PAPEL",Tabla2[[#This Row],[Doble faz]]="NO",Tabla2[[#This Row],[Impresora]]='Insumos y gastos'!$L$6),M18*'Insumos y gastos'!$M$15,IF(AND(Tabla2[[#This Row],[Tipo de insumo]]="PAPEL",Tabla2[[#This Row],[Doble faz]]="NO",Tabla2[[#This Row],[Impresora]]='Insumos y gastos'!$N$6),M18*'Insumos y gastos'!$O$15,IF(AND(Tabla2[[#This Row],[Tipo de insumo]]="PAPEL",Tabla2[[#This Row],[Doble faz]]="NO",Tabla2[[#This Row],[Impresora]]='Insumos y gastos'!$P$6),M18*'Insumos y gastos'!$Q$15,IF(AND(Tabla2[[#This Row],[Tipo de insumo]]="PAPEL",Tabla2[[#This Row],[Doble faz]]="NO",Tabla2[[#This Row],[Impresora]]='Insumos y gastos'!$R$6),M18*'Insumos y gastos'!$S$15,IF(AND(Tabla2[[#This Row],[Tipo de insumo]]="PAPEL",Tabla2[[#This Row],[Doble faz]]="NO",Tabla2[[#This Row],[Impresora]]='Insumos y gastos'!$T$6),M18*'Insumos y gastos'!$U$15,0)))))))))))) -> 0 | R18: =Tabla2[[#This Row],[Costo impresión]]+Tabla2[[#This Row],[Total costo insumo]] -> 0
K19: =IFERROR(VLOOKUP(J19,'Insumos y gastos'!$B$13:$C$83,2,0),"") -> 0 | L19: =IFERROR(VLOOKUP(J19,Tabla1[[#All],[Nombre insumo]:[Pr. Unidad]],4,0),0) -> 0 | N19: =Tabla2[[#This Row],[Cantidad]]*Tabla2[[#This Row],[Costo insumo]] -> 0 | Q19: =IF(AND(Tabla2[[#This Row],[Tipo de insumo]]="PAPEL",Tabla2[[#This Row],[Doble faz]]="SI",Tabla2[[#This Row],[Impresora]]='Insumos y gastos'!$J$6),M19*'Insumos y gastos'!$K$15*2,IF(AND(Tabla2[[#This Row],[Tipo de insumo]]="PAPEL",Tabla2[[#This Row],[Doble faz]]="SI",Tabla2[[#This Row],[Impresora]]='Insumos y gastos'!$L$6),M19*'Insumos y gastos'!$M$15*2,IF(AND(Tabla2[[#This Row],[Tipo de insumo]]="PAPEL",Tabla2[[#This Row],[Doble faz]]="SI",Tabla2[[#This Row],[Impresora]]='Insumos y gastos'!$N$6),M19*'Insumos y gastos'!$O$15*2,IF(AND(Tabla2[[#This Row],[Tipo de insumo]]="PAPEL",Tabla2[[#This Row],[Doble faz]]="SI",Tabla2[[#This Row],[Impresora]]='Insumos y gastos'!$P$6),M19*'Insumos y gastos'!$Q$15*2,IF(AND(Tabla2[[#This Row],[Tipo de insumo]]="PAPEL",Tabla2[[#This Row],[Doble faz]]="SI",Tabla2[[#This Row],[Impresora]]='Insumos y gastos'!$R$6),M19*'Insumos y gastos'!$S$15*2,IF(AND(Tabla2[[#This Row],[Tipo de insumo]]="PAPEL",Tabla2[[#This Row],[Doble faz]]="SI",Tabla2[[#This Row],[Impresora]]='Insumos y gastos'!$T$6),M19*'Insumos y gastos'!$U$15*2,IF(AND(Tabla2[[#This Row],[Tipo de insumo]]="PAPEL",Tabla2[[#This Row],[Doble faz]]="NO",Tabla2[[#This Row],[Impresora]]='Insumos y gastos'!$J$6),M19*'Insumos y gastos'!$K$15,IF(AND(Tabla2[[#This Row],[Tipo de insumo]]="PAPEL",Tabla2[[#This Row],[Doble faz]]="NO",Tabla2[[#This Row],[Impresora]]='Insumos y gastos'!$L$6),M19*'Insumos y gastos'!$M$15,IF(AND(Tabla2[[#This Row],[Tipo de insumo]]="PAPEL",Tabla2[[#This Row],[Doble faz]]="NO",Tabla2[[#This Row],[Impresora]]='Insumos y gastos'!$N$6),M19*'Insumos y gastos'!$O$15,IF(AND(Tabla2[[#This Row],[Tipo de insumo]]="PAPEL",Tabla2[[#This Row],[Doble faz]]="NO",Tabla2[[#This Row],[Impresora]]='Insumos y gastos'!$P$6),M19*'Insumos y gastos'!$Q$15,IF(AND(Tabla2[[#This Row],[Tipo de insumo]]="PAPEL",Tabla2[[#This Row],[Doble faz]]="NO",Tabla2[[#This Row],[Impresora]]='Insumos y gastos'!$R$6),M19*'Insumos y gastos'!$S$15,IF(AND(Tabla2[[#This Row],[Tipo de insumo]]="PAPEL",Tabla2[[#This Row],[Doble faz]]="NO",Tabla2[[#This Row],[Impresora]]='Insumos y gastos'!$T$6),M19*'Insumos y gastos'!$U$15,0)))))))))))) -> 0 | R19: =Tabla2[[#This Row],[Costo impresión]]+Tabla2[[#This Row],[Total costo insumo]] -> 0
K20: =IFERROR(VLOOKUP(J20,'Insumos y gastos'!$B$13:$C$83,2,0),"") -> 0 | L20: =IFERROR(VLOOKUP(J20,Tabla1[[#All],[Nombre insumo]:[Pr. Unidad]],4,0),0) -> 0 | N20: =Tabla2[[#This Row],[Cantidad]]*Tabla2[[#This Row],[Costo insumo]] -> 0 | Q20: =IF(AND(Tabla2[[#This Row],[Tipo de insumo]]="PAPEL",Tabla2[[#This Row],[Doble faz]]="SI",Tabla2[[#This Row],[Impresora]]='Insumos y gastos'!$J$6),M20*'Insumos y gastos'!$K$15*2,IF(AND(Tabla2[[#This Row],[Tipo de insumo]]="PAPEL",Tabla2[[#This Row],[Doble faz]]="SI",Tabla2[[#This Row],[Impresora]]='Insumos y gastos'!$L$6),M20*'Insumos y gastos'!$M$15*2,IF(AND(Tabla2[[#This Row],[Tipo de insumo]]="PAPEL",Tabla2[[#This Row],[Doble faz]]="SI",Tabla2[[#This Row],[Impresora]]='Insumos y gastos'!$N$6),M20*'Insumos y gastos'!$O$15*2,IF(AND(Tabla2[[#This Row],[Tipo de insumo]]="PAPEL",Tabla2[[#This Row],[Doble faz]]="SI",Tabla2[[#This Row],[Impresora]]='Insumos y gastos'!$P$6),M20*'Insumos y gastos'!$Q$15*2,IF(AND(Tabla2[[#This Row],[Tipo de insumo]]="PAPEL",Tabla2[[#This Row],[Doble faz]]="SI",Tabla2[[#This Row],[Impresora]]='Insumos y gastos'!$R$6),M20*'Insumos y gastos'!$S$15*2,IF(AND(Tabla2[[#This Row],[Tipo de insumo]]="PAPEL",Tabla2[[#This Row],[Doble faz]]="SI",Tabla2[[#This Row],[Impresora]]='Insumos y gastos'!$T$6),M20*'Insumos y gastos'!$U$15*2,IF(AND(Tabla2[[#This Row],[Tipo de insumo]]="PAPEL",Tabla2[[#This Row],[Doble faz]]="NO",Tabla2[[#This Row],[Impresora]]='Insumos y gastos'!$J$6),M20*'Insumos y gastos'!$K$15,IF(AND(Tabla2[[#This Row],[Tipo de insumo]]="PAPEL",Tabla2[[#This Row],[Doble faz]]="NO",Tabla2[[#This Row],[Impresora]]='Insumos y gastos'!$L$6),M20*'Insumos y gastos'!$M$15,IF(AND(Tabla2[[#This Row],[Tipo de insumo]]="PAPEL",Tabla2[[#This Row],[Doble faz]]="NO",Tabla2[[#This Row],[Impresora]]='Insumos y gastos'!$N$6),M20*'Insumos y gastos'!$O$15,IF(AND(Tabla2[[#This Row],[Tipo de insumo]]="PAPEL",Tabla2[[#This Row],[Doble faz]]="NO",Tabla2[[#This Row],[Impresora]]='Insumos y gastos'!$P$6),M20*'Insumos y gastos'!$Q$15,IF(AND(Tabla2[[#This Row],[Tipo de insumo]]="PAPEL",Tabla2[[#This Row],[Doble faz]]="NO",Tabla2[[#This Row],[Impresora]]='Insumos y gastos'!$R$6),M20*'Insumos y gastos'!$S$15,IF(AND(Tabla2[[#This Row],[Tipo de insumo]]="PAPEL",Tabla2[[#This Row],[Doble faz]]="NO",Tabla2[[#This Row],[Impresora]]='Insumos y gastos'!$T$6),M20*'Insumos y gastos'!$U$15,0)))))))))))) -> 0 | R20: =Tabla2[[#This Row],[Costo impresión]]+Tabla2[[#This Row],[Total costo insumo]] -> 0
K21: =IFERROR(VLOOKUP(J21,'Insumos y gastos'!$B$13:$C$83,2,0),"") -> 0 | L21: =IFERROR(VLOOKUP(J21,Tabla1[[#All],[Nombre insumo]:[Pr. Unidad]],4,0),0) -> 0 | N21: =Tabla2[[#This Row],[Cantidad]]*Tabla2[[#This Row],[Costo insumo]] -> 0 | Q21: =IF(AND(Tabla2[[#This Row],[Tipo de insumo]]="PAPEL",Tabla2[[#This Row],[Doble faz]]="SI",Tabla2[[#This Row],[Impresora]]='Insumos y gastos'!$J$6),M21*'Insumos y gastos'!$K$15*2,IF(AND(Tabla2[[#This Row],[Tipo de insumo]]="PAPEL",Tabla2[[#This Row],[Doble faz]]="SI",Tabla2[[#This Row],[Impresora]]='Insumos y gastos'!$L$6),M21*'Insumos y gastos'!$M$15*2,IF(AND(Tabla2[[#This Row],[Tipo de insumo]]="PAPEL",Tabla2[[#This Row],[Doble faz]]="SI",Tabla2[[#This Row],[Impresora]]='Insumos y gastos'!$N$6),M21*'Insumos y gastos'!$O$15*2,IF(AND(Tabla2[[#This Row],[Tipo de insumo]]="PAPEL",Tabla2[[#This Row],[Doble faz]]="SI",Tabla2[[#This Row],[Impresora]]='Insumos y gastos'!$P$6),M21*'Insumos y gastos'!$Q$15*2,IF(AND(Tabla2[[#This Row],[Tipo de insumo]]="PAPEL",Tabla2[[#This Row],[Doble faz]]="SI",Tabla2[[#This Row],[Impresora]]='Insumos y gastos'!$R$6),M21*'Insumos y gastos'!$S$15*2,IF(AND(Tabla2[[#This Row],[Tipo de insumo]]="PAPEL",Tabla2[[#This Row],[Doble faz]]="SI",Tabla2[[#This Row],[Impresora]]='Insumos y gastos'!$T$6),M21*'Insumos y gastos'!$U$15*2,IF(AND(Tabla2[[#This Row],[Tipo de insumo]]="PAPEL",Tabla2[[#This Row],[Doble faz]]="NO",Tabla2[[#This Row],[Impresora]]='Insumos y gastos'!$J$6),M21*'Insumos y gastos'!$K$15,IF(AND(Tabla2[[#This Row],[Tipo de insumo]]="PAPEL",Tabla2[[#This Row],[Doble faz]]="NO",Tabla2[[#This Row],[Impresora]]='Insumos y gastos'!$L$6),M21*'Insumos y gastos'!$M$15,IF(AND(Tabla2[[#This Row],[Tipo de insumo]]="PAPEL",Tabla2[[#This Row],[Doble faz]]="NO",Tabla2[[#This Row],[Impresora]]='Insumos y gastos'!$N$6),M21*'Insumos y gastos'!$O$15,IF(AND(Tabla2[[#This Row],[Tipo de insumo]]="PAPEL",Tabla2[[#This Row],[Doble faz]]="NO",Tabla2[[#This Row],[Impresora]]='Insumos y gastos'!$P$6),M21*'Insumos y gastos'!$Q$15,IF(AND(Tabla2[[#This Row],[Tipo de insumo]]="PAPEL",Tabla2[[#This Row],[Doble faz]]="NO",Tabla2[[#This Row],[Impresora]]='Insumos y gastos'!$R$6),M21*'Insumos y gastos'!$S$15,IF(AND(Tabla2[[#This Row],[Tipo de insumo]]="PAPEL",Tabla2[[#This Row],[Doble faz]]="NO",Tabla2[[#This Row],[Impresora]]='Insumos y gastos'!$T$6),M21*'Insumos y gastos'!$U$15,0)))))))))))) -> 0 | R21: =Tabla2[[#This Row],[Costo impresión]]+Tabla2[[#This Row],[Total costo insumo]] -> 0
K22: =IFERROR(VLOOKUP(J22,'Insumos y gastos'!$B$13:$C$83,2,0),"") -> 0 | L22: =IFERROR(VLOOKUP(J22,Tabla1[[#All],[Nombre insumo]:[Pr. Unidad]],4,0),0) -> 0 | N22: =Tabla2[[#This Row],[Cantidad]]*Tabla2[[#This Row],[Costo insumo]] -> 0 | Q22: =IF(AND(Tabla2[[#This Row],[Tipo de insumo]]="PAPEL",Tabla2[[#This Row],[Doble faz]]="SI",Tabla2[[#This Row],[Impresora]]='Insumos y gastos'!$J$6),M22*'Insumos y gastos'!$K$15*2,IF(AND(Tabla2[[#This Row],[Tipo de insumo]]="PAPEL",Tabla2[[#This Row],[Doble faz]]="SI",Tabla2[[#This Row],[Impresora]]='Insumos y gastos'!$L$6),M22*'Insumos y gastos'!$M$15*2,IF(AND(Tabla2[[#This Row],[Tipo de insumo]]="PAPEL",Tabla2[[#This Row],[Doble faz]]="SI",Tabla2[[#This Row],[Impresora]]='Insumos y gastos'!$N$6),M22*'Insumos y gastos'!$O$15*2,IF(AND(Tabla2[[#This Row],[Tipo de insumo]]="PAPEL",Tabla2[[#This Row],[Doble faz]]="SI",Tabla2[[#This Row],[Impresora]]='Insumos y gastos'!$P$6),M22*'Insumos y gastos'!$Q$15*2,IF(AND(Tabla2[[#This Row],[Tipo de insumo]]="PAPEL",Tabla2[[#This Row],[Doble faz]]="SI",Tabla2[[#This Row],[Impresora]]='Insumos y gastos'!$R$6),M22*'Insumos y gastos'!$S$15*2,IF(AND(Tabla2[[#This Row],[Tipo de insumo]]="PAPEL",Tabla2[[#This Row],[Doble faz]]="SI",Tabla2[[#This Row],[Impresora]]='Insumos y gastos'!$T$6),M22*'Insumos y gastos'!$U$15*2,IF(AND(Tabla2[[#This Row],[Tipo de insumo]]="PAPEL",Tabla2[[#This Row],[Doble faz]]="NO",Tabla2[[#This Row],[Impresora]]='Insumos y gastos'!$J$6),M22*'Insumos y gastos'!$K$15,IF(AND(Tabla2[[#This Row],[Tipo de insumo]]="PAPEL",Tabla2[[#This Row],[Doble faz]]="NO",Tabla2[[#This Row],[Impresora]]='Insumos y gastos'!$L$6),M22*'Insumos y gastos'!$M$15,IF(AND(Tabla2[[#This Row],[Tipo de insumo]]="PAPEL",Tabla2[[#This Row],[Doble faz]]="NO",Tabla2[[#This Row],[Impresora]]='Insumos y gastos'!$N$6),M22*'Insumos y gastos'!$O$15,IF(AND(Tabla2[[#This Row],[Tipo de insumo]]="PAPEL",Tabla2[[#This Row],[Doble faz]]="NO",Tabla2[[#This Row],[Impresora]]='Insumos y gastos'!$P$6),M22*'Insumos y gastos'!$Q$15,IF(AND(Tabla2[[#This Row],[Tipo de insumo]]="PAPEL",Tabla2[[#This Row],[Doble faz]]="NO",Tabla2[[#This Row],[Impresora]]='Insumos y gastos'!$R$6),M22*'Insumos y gastos'!$S$15,IF(AND(Tabla2[[#This Row],[Tipo de insumo]]="PAPEL",Tabla2[[#This Row],[Doble faz]]="NO",Tabla2[[#This Row],[Impresora]]='Insumos y gastos'!$T$6),M22*'Insumos y gastos'!$U$15,0)))))))))))) -> 0 | R22: =Tabla2[[#This Row],[Costo impresión]]+Tabla2[[#This Row],[Total costo insumo]] -> 0
K23: =IFERROR(VLOOKUP(J23,'Insumos y gastos'!$B$13:$C$83,2,0),"") -> 0 | L23: =IFERROR(VLOOKUP(J23,Tabla1[[#All],[Nombre insumo]:[Pr. Unidad]],4,0),0) -> 0 | N23: =Tabla2[[#This Row],[Cantidad]]*Tabla2[[#This Row],[Costo insumo]] -> 0 | Q23: =IF(AND(Tabla2[[#This Row],[Tipo de insumo]]="PAPEL",Tabla2[[#This Row],[Doble faz]]="SI",Tabla2[[#This Row],[Impresora]]='Insumos y gastos'!$J$6),M23*'Insumos y gastos'!$K$15*2,IF(AND(Tabla2[[#This Row],[Tipo de insumo]]="PAPEL",Tabla2[[#This Row],[Doble faz]]="SI",Tabla2[[#This Row],[Impresora]]='Insumos y gastos'!$L$6),M23*'Insumos y gastos'!$M$15*2,IF(AND(Tabla2[[#This Row],[Tipo de insumo]]="PAPEL",Tabla2[[#This Row],[Doble faz]]="SI",Tabla2[[#This Row],[Impresora]]='Insumos y gastos'!$N$6),M23*'Insumos y gastos'!$O$15*2,IF(AND(Tabla2[[#This Row],[Tipo de insumo]]="PAPEL",Tabla2[[#This Row],[Doble faz]]="SI",Tabla2[[#This Row],[Impresora]]='Insumos y gastos'!$P$6),M23*'Insumos y gastos'!$Q$15*2,IF(AND(Tabla2[[#This Row],[Tipo de insumo]]="PAPEL",Tabla2[[#This Row],[Doble faz]]="SI",Tabla2[[#This Row],[Impresora]]='Insumos y gastos'!$R$6),M23*'Insumos y gastos'!$S$15*2,IF(AND(Tabla2[[#This Row],[Tipo de insumo]]="PAPEL",Tabla2[[#This Row],[Doble faz]]="SI",Tabla2[[#This Row],[Impresora]]='Insumos y gastos'!$T$6),M23*'Insumos y gastos'!$U$15*2,IF(AND(Tabla2[[#This Row],[Tipo de insumo]]="PAPEL",Tabla2[[#This Row],[Doble faz]]="NO",Tabla2[[#This Row],[Impresora]]='Insumos y gastos'!$J$6),M23*'Insumos y gastos'!$K$15,IF(AND(Tabla2[[#This Row],[Tipo de insumo]]="PAPEL",Tabla2[[#This Row],[Doble faz]]="NO",Tabla2[[#This Row],[Impresora]]='Insumos y gastos'!$L$6),M23*'Insumos y gastos'!$M$15,IF(AND(Tabla2[[#This Row],[Tipo de insumo]]="PAPEL",Tabla2[[#This Row],[Doble faz]]="NO",Tabla2[[#This Row],[Impresora]]='Insumos y gastos'!$N$6),M23*'Insumos y gastos'!$O$15,IF(AND(Tabla2[[#This Row],[Tipo de insumo]]="PAPEL",Tabla2[[#This Row],[Doble faz]]="NO",Tabla2[[#This Row],[Impresora]]='Insumos y gastos'!$P$6),M23*'Insumos y gastos'!$Q$15,IF(AND(Tabla2[[#This Row],[Tipo de insumo]]="PAPEL",Tabla2[[#This Row],[Doble faz]]="NO",Tabla2[[#This Row],[Impresora]]='Insumos y gastos'!$R$6),M23*'Insumos y gastos'!$S$15,IF(AND(Tabla2[[#This Row],[Tipo de insumo]]="PAPEL",Tabla2[[#This Row],[Doble faz]]="NO",Tabla2[[#This Row],[Impresora]]='Insumos y gastos'!$T$6),M23*'Insumos y gastos'!$U$15,0)))))))))))) -> 0 | R23: =Tabla2[[#This Row],[Costo impresión]]+Tabla2[[#This Row],[Total costo insumo]] -> 0
J24: Total | N24: =SUBTOTAL(109,Tabla2[Total costo insumo]) -> 0 | Q24: =SUBTOTAL(109,Tabla2[Costo impresión]) -> 0 | R24: =SUBTOTAL(109,Tabla2[Total insumo + impresión]) -> 0
R25: (*)
J26: (*) El total no incluye gastos fijos, ni hora de mano de obra, solo costo de insumos.
P28: Calculadora de horas
J30: Costo sin servicios | K30: Cantidad de horas | L30: Costo sevicios | M30: Mano de obra | N30: Costo final | P30: Minutos | Q30: Porcentaje horario
J31: =Tabla2[[#Totals],[Total insumo + impresión]] -> 0 | L31: =K31*'Insumos y gastos'!$M$50 -> 0 | M31: =K31*'Insumos y gastos'!$Q$24 -> 0 | N31: =J31+L31+M31 -> 0 | Q31: =P31/60 -> 0
K36: Precio final | O36: Precio final
K38: ¿Cuanto porcentaje de ganancia tengo? ❤ | O38: ¿A cuanto debo venderlo? ❤
K40: Precio publicado | L40: Porcentaje de ganancia | M40: Ganancia en pesos | O40: Porcentaje de ganancia | P40: Precio sugerido | Q40: Ganancia en pesos
L41: =((K41*100)/N31)/100 -> #DIV/0! | M41: =K41-N31 -> 0 | P41: =(O41*N31)+N31 -> 0 | Q41: =P41-N31 -> 0

Sheet Productos
A1: PRODUCTO | E1: COSTOS DE PAPELES E IMPRESIÓN | AN1: COSTO INSUMOS | BH1: Costo final
A2: SKU | B2: Nombre producto | C2: RUBRO | D2: SUBRUBRO | E2: Papel 1 | F2: Costo papel 1 | G2: Cantidad 1 | H2: Doble faz 1 | I2: Impresora 1 | J2: Costo impresión 1 | K2: Subtotal impresión 1 | L2: Papel 2 | M2: Costo papel 2 | N2: Cantidad 2 | O2: Doble faz 2 | P2: Impresora 2 | Q2: Costo impresión 2 | R2: Subtotal impresión 2 | S2: Papel 3 | T2: Costo papel 3 | U2: Cantidad 3 | V2: Doble faz 3 | W2: Impresora 3 | X2: Costo impresión 3 | Y2: Subtotal impresión 3 | Z2: Papel 4 | AA2: Costo papel 4 | AB2: Cantidad 4 | AC2: Doble faz 4 | AD2: Impresora 4 | AE2: Costo impresión 4 | AF2: Subtotal impresión 4 | AG2: Papel 5 | AH2: Costo papel 5 | AI2: Cantidad 5 | AJ2: Doble faz 5 | AK2: Impresora 5 | AL2: Costo impresión 5 | AM2: Subtotal impresión 5 | AN2: Insumo 1 | AO2: Costo insumo 1 | AP2: Cantidad insumo 1 | AQ2: Subtotal insumos 1 | AR2: Insumo 2 | AS2: Costo insumo 2 | AT2: Cantidad insumo 2 | AU2: Subtotal insumos 2 | AV2: Insumo 3 | AW2: Costo insumo 3 | AX2: Cantidad insumo 3 | AY2: Subtotal insumos 3 | AZ2: Insumo 4 | BA2: Costo insumo 4 | BB2: Cantidad insumo 4 | BC2: Subtotal insumos 4 | BD2: Insumo 5 | BE2: Costo insumo 5 | BF2: Cantidad insumo 5 | BG2: Subtotal insumos 5 | BH2: Costo sin servicios | BI2: Cantidad de horas | BJ2: Costo servicios | BK2: Costo mano de obra | BL2: Costo total
